2020-08-11 12:06:18,982 ERROR: Exception on /login [GET] [in /mnt/c/Users/ASUS/Documents/webdev/microblog/venv/lib/python3.8/site-packages/flask/app.py:1891]
Traceback (most recent call last):
  File "/mnt/c/Users/ASUS/Documents/webdev/microblog/venv/lib/python3.8/site-packages/flask/app.py", line 2447, in wsgi_app
    response = self.full_dispatch_request()
  File "/mnt/c/Users/ASUS/Documents/webdev/microblog/venv/lib/python3.8/site-packages/flask/app.py", line 1952, in full_dispatch_request
    rv = self.handle_user_exception(e)
  File "/mnt/c/Users/ASUS/Documents/webdev/microblog/venv/lib/python3.8/site-packages/flask/app.py", line 1821, in handle_user_exception
    reraise(exc_type, exc_value, tb)
  File "/mnt/c/Users/ASUS/Documents/webdev/microblog/venv/lib/python3.8/site-packages/flask/_compat.py", line 39, in reraise
    raise value
  File "/mnt/c/Users/ASUS/Documents/webdev/microblog/venv/lib/python3.8/site-packages/flask/app.py", line 1950, in full_dispatch_request
    rv = self.dispatch_request()
  File "/mnt/c/Users/ASUS/Documents/webdev/microblog/venv/lib/python3.8/site-packages/flask/app.py", line 1936, in dispatch_request
    return self.view_functions[rule.endpoint](**req.view_args)
  File "/mnt/c/Users/ASUS/Documents/webdev/microblog/app/routes.py", line 50, in login
    return render_template('login.html', title='Sign In', form=form)
  File "/mnt/c/Users/ASUS/Documents/webdev/microblog/venv/lib/python3.8/site-packages/flask/templating.py", line 138, in render_template
    ctx.app.jinja_env.get_or_select_template(template_name_or_list),
  File "/mnt/c/Users/ASUS/Documents/webdev/microblog/venv/lib/python3.8/site-packages/jinja2/environment.py", line 930, in get_or_select_template
    return self.get_template(template_name_or_list, parent, globals)
  File "/mnt/c/Users/ASUS/Documents/webdev/microblog/venv/lib/python3.8/site-packages/jinja2/environment.py", line 883, in get_template
    return self._load_template(name, self.make_globals(globals))
  File "/mnt/c/Users/ASUS/Documents/webdev/microblog/venv/lib/python3.8/site-packages/jinja2/environment.py", line 857, in _load_template
    template = self.loader.load(self, name, globals)
  File "/mnt/c/Users/ASUS/Documents/webdev/microblog/venv/lib/python3.8/site-packages/jinja2/loaders.py", line 127, in load
    code = environment.compile(source, name, filename)
  File "/mnt/c/Users/ASUS/Documents/webdev/microblog/venv/lib/python3.8/site-packages/jinja2/environment.py", line 638, in compile
    self.handle_exception(source=source_hint)
  File "/mnt/c/Users/ASUS/Documents/webdev/microblog/venv/lib/python3.8/site-packages/jinja2/environment.py", line 832, in handle_exception
    reraise(*rewrite_traceback_stack(source=source))
  File "/mnt/c/Users/ASUS/Documents/webdev/microblog/venv/lib/python3.8/site-packages/jinja2/_compat.py", line 28, in reraise
    raise value.with_traceback(tb)
  File "/mnt/c/Users/ASUS/Documents/webdev/microblog/app/templates/login.html", line 20, in template
    {% block app_content %}
jinja2.exceptions.TemplateAssertionError: block 'app_content' defined twice
2020-08-11 12:10:53,462 INFO: Microblog startup [in /mnt/c/Users/ASUS/Documents/webdev/microblog/app/__init__.py:47]
2020-08-11 12:13:16,978 INFO: Microblog startup [in /mnt/c/Users/ASUS/Documents/webdev/microblog/app/__init__.py:47]
2020-08-11 14:33:39,556 INFO: Microblog startup [in /mnt/c/Users/ASUS/Documents/webdev/microblog/app/__init__.py:49]
2020-08-11 20:14:50,656 INFO: Microblog startup [in /mnt/c/Users/ASUS/Documents/webdev/microblog/app/__init__.py:51]
2020-08-11 20:21:02,081 INFO: Microblog startup [in /mnt/c/Users/ASUS/Documents/webdev/microblog/app/__init__.py:53]
2020-08-11 20:25:31,130 INFO: Microblog startup [in /mnt/c/Users/ASUS/Documents/webdev/microblog/app/__init__.py:53]
2020-08-11 20:25:36,406 ERROR: Exception on /login [GET] [in /mnt/c/Users/ASUS/Documents/webdev/microblog/venv/lib/python3.8/site-packages/flask/app.py:1891]
Traceback (most recent call last):
  File "/mnt/c/Users/ASUS/Documents/webdev/microblog/venv/lib/python3.8/site-packages/flask/app.py", line 2447, in wsgi_app
    response = self.full_dispatch_request()
  File "/mnt/c/Users/ASUS/Documents/webdev/microblog/venv/lib/python3.8/site-packages/flask/app.py", line 1952, in full_dispatch_request
    rv = self.handle_user_exception(e)
  File "/mnt/c/Users/ASUS/Documents/webdev/microblog/venv/lib/python3.8/site-packages/flask/app.py", line 1821, in handle_user_exception
    reraise(exc_type, exc_value, tb)
  File "/mnt/c/Users/ASUS/Documents/webdev/microblog/venv/lib/python3.8/site-packages/flask/_compat.py", line 39, in reraise
    raise value
  File "/mnt/c/Users/ASUS/Documents/webdev/microblog/venv/lib/python3.8/site-packages/flask/app.py", line 1950, in full_dispatch_request
    rv = self.dispatch_request()
  File "/mnt/c/Users/ASUS/Documents/webdev/microblog/venv/lib/python3.8/site-packages/flask/app.py", line 1936, in dispatch_request
    return self.view_functions[rule.endpoint](**req.view_args)
  File "/mnt/c/Users/ASUS/Documents/webdev/microblog/app/routes.py", line 50, in login
    return render_template('login.html', title='Sign In', form=form)
  File "/mnt/c/Users/ASUS/Documents/webdev/microblog/venv/lib/python3.8/site-packages/flask/templating.py", line 138, in render_template
    ctx.app.jinja_env.get_or_select_template(template_name_or_list),
  File "/mnt/c/Users/ASUS/Documents/webdev/microblog/venv/lib/python3.8/site-packages/jinja2/environment.py", line 930, in get_or_select_template
    return self.get_template(template_name_or_list, parent, globals)
  File "/mnt/c/Users/ASUS/Documents/webdev/microblog/venv/lib/python3.8/site-packages/jinja2/environment.py", line 883, in get_template
    return self._load_template(name, self.make_globals(globals))
  File "/mnt/c/Users/ASUS/Documents/webdev/microblog/venv/lib/python3.8/site-packages/jinja2/environment.py", line 857, in _load_template
    template = self.loader.load(self, name, globals)
  File "/mnt/c/Users/ASUS/Documents/webdev/microblog/venv/lib/python3.8/site-packages/jinja2/loaders.py", line 127, in load
    code = environment.compile(source, name, filename)
  File "/mnt/c/Users/ASUS/Documents/webdev/microblog/venv/lib/python3.8/site-packages/jinja2/environment.py", line 638, in compile
    self.handle_exception(source=source_hint)
  File "/mnt/c/Users/ASUS/Documents/webdev/microblog/venv/lib/python3.8/site-packages/jinja2/environment.py", line 832, in handle_exception
    reraise(*rewrite_traceback_stack(source=source))
  File "/mnt/c/Users/ASUS/Documents/webdev/microblog/venv/lib/python3.8/site-packages/jinja2/_compat.py", line 28, in reraise
    raise value.with_traceback(tb)
  File "/mnt/c/Users/ASUS/Documents/webdev/microblog/app/templates/login.html", line 39, in template
    <p>New User? <a href="{{ url_for('register') }}">Click to Register!</a></p>
jinja2.exceptions.TemplateSyntaxError: expected token ',', got 'register'
2020-08-11 20:26:19,323 INFO: Microblog startup [in /mnt/c/Users/ASUS/Documents/webdev/microblog/app/__init__.py:53]
2020-08-11 20:26:21,571 ERROR: Exception on /login [GET] [in /mnt/c/Users/ASUS/Documents/webdev/microblog/venv/lib/python3.8/site-packages/flask/app.py:1891]
Traceback (most recent call last):
  File "/mnt/c/Users/ASUS/Documents/webdev/microblog/venv/lib/python3.8/site-packages/flask/app.py", line 2447, in wsgi_app
    response = self.full_dispatch_request()
  File "/mnt/c/Users/ASUS/Documents/webdev/microblog/venv/lib/python3.8/site-packages/flask/app.py", line 1952, in full_dispatch_request
    rv = self.handle_user_exception(e)
  File "/mnt/c/Users/ASUS/Documents/webdev/microblog/venv/lib/python3.8/site-packages/flask/app.py", line 1821, in handle_user_exception
    reraise(exc_type, exc_value, tb)
  File "/mnt/c/Users/ASUS/Documents/webdev/microblog/venv/lib/python3.8/site-packages/flask/_compat.py", line 39, in reraise
    raise value
  File "/mnt/c/Users/ASUS/Documents/webdev/microblog/venv/lib/python3.8/site-packages/flask/app.py", line 1950, in full_dispatch_request
    rv = self.dispatch_request()
  File "/mnt/c/Users/ASUS/Documents/webdev/microblog/venv/lib/python3.8/site-packages/flask/app.py", line 1936, in dispatch_request
    return self.view_functions[rule.endpoint](**req.view_args)
  File "/mnt/c/Users/ASUS/Documents/webdev/microblog/app/routes.py", line 50, in login
    return render_template('login.html', title='Sign In', form=form)
  File "/mnt/c/Users/ASUS/Documents/webdev/microblog/venv/lib/python3.8/site-packages/flask/templating.py", line 138, in render_template
    ctx.app.jinja_env.get_or_select_template(template_name_or_list),
  File "/mnt/c/Users/ASUS/Documents/webdev/microblog/venv/lib/python3.8/site-packages/jinja2/environment.py", line 930, in get_or_select_template
    return self.get_template(template_name_or_list, parent, globals)
  File "/mnt/c/Users/ASUS/Documents/webdev/microblog/venv/lib/python3.8/site-packages/jinja2/environment.py", line 883, in get_template
    return self._load_template(name, self.make_globals(globals))
  File "/mnt/c/Users/ASUS/Documents/webdev/microblog/venv/lib/python3.8/site-packages/jinja2/environment.py", line 857, in _load_template
    template = self.loader.load(self, name, globals)
  File "/mnt/c/Users/ASUS/Documents/webdev/microblog/venv/lib/python3.8/site-packages/jinja2/loaders.py", line 127, in load
    code = environment.compile(source, name, filename)
  File "/mnt/c/Users/ASUS/Documents/webdev/microblog/venv/lib/python3.8/site-packages/jinja2/environment.py", line 638, in compile
    self.handle_exception(source=source_hint)
  File "/mnt/c/Users/ASUS/Documents/webdev/microblog/venv/lib/python3.8/site-packages/jinja2/environment.py", line 832, in handle_exception
    reraise(*rewrite_traceback_stack(source=source))
  File "/mnt/c/Users/ASUS/Documents/webdev/microblog/venv/lib/python3.8/site-packages/jinja2/_compat.py", line 28, in reraise
    raise value.with_traceback(tb)
  File "/mnt/c/Users/ASUS/Documents/webdev/microblog/app/templates/login.html", line 15, in template
    <a href="{{ url_for('reset_password_request') }}">{{_('Click to Reset It)}}</a>
jinja2.exceptions.TemplateSyntaxError: unexpected char "'" at 418
