2020-08-12 01:11:32,555 ERROR: Exception on /index [GET] [in /mnt/c/Users/ASUS/Documents/webdev/microblog/venv/lib/python3.8/site-packages/flask/app.py:1891]
Traceback (most recent call last):
  File "/mnt/c/Users/ASUS/Documents/webdev/microblog/venv/lib/python3.8/site-packages/flask/app.py", line 2447, in wsgi_app
    response = self.full_dispatch_request()
  File "/mnt/c/Users/ASUS/Documents/webdev/microblog/venv/lib/python3.8/site-packages/flask/app.py", line 1952, in full_dispatch_request
    rv = self.handle_user_exception(e)
  File "/mnt/c/Users/ASUS/Documents/webdev/microblog/venv/lib/python3.8/site-packages/flask/app.py", line 1821, in handle_user_exception
    reraise(exc_type, exc_value, tb)
  File "/mnt/c/Users/ASUS/Documents/webdev/microblog/venv/lib/python3.8/site-packages/flask/_compat.py", line 39, in reraise
    raise value
  File "/mnt/c/Users/ASUS/Documents/webdev/microblog/venv/lib/python3.8/site-packages/flask/app.py", line 1950, in full_dispatch_request
    rv = self.dispatch_request()
  File "/mnt/c/Users/ASUS/Documents/webdev/microblog/venv/lib/python3.8/site-packages/flask/app.py", line 1936, in dispatch_request
    return self.view_functions[rule.endpoint](**req.view_args)
  File "/mnt/c/Users/ASUS/Documents/webdev/microblog/venv/lib/python3.8/site-packages/flask_login/utils.py", line 272, in decorated_view
    return func(*args, **kwargs)
  File "/mnt/c/Users/ASUS/Documents/webdev/microblog/app/routes.py", line 32, in index
    return render_template('index.html', title='Home', form=form,
  File "/mnt/c/Users/ASUS/Documents/webdev/microblog/venv/lib/python3.8/site-packages/flask/templating.py", line 137, in render_template
    return _render(
  File "/mnt/c/Users/ASUS/Documents/webdev/microblog/venv/lib/python3.8/site-packages/flask/templating.py", line 120, in _render
    rv = template.render(context)
  File "/mnt/c/Users/ASUS/Documents/webdev/microblog/venv/lib/python3.8/site-packages/jinja2/environment.py", line 1090, in render
    self.environment.handle_exception()
  File "/mnt/c/Users/ASUS/Documents/webdev/microblog/venv/lib/python3.8/site-packages/jinja2/environment.py", line 832, in handle_exception
    reraise(*rewrite_traceback_stack(source=source))
  File "/mnt/c/Users/ASUS/Documents/webdev/microblog/venv/lib/python3.8/site-packages/jinja2/_compat.py", line 28, in reraise
    raise value.with_traceback(tb)
  File "/mnt/c/Users/ASUS/Documents/webdev/microblog/app/templates/index.html", line 2, in top-level template code
    {% import 'bootstrap/wtf.html' as wtf %}
  File "/mnt/c/Users/ASUS/Documents/webdev/microblog/app/templates/base.html", line 1, in top-level template code
    {% extends 'bootstrap/base.html' %}
  File "/mnt/c/Users/ASUS/Documents/webdev/microblog/venv/lib/python3.8/site-packages/flask_bootstrap/templates/bootstrap/base.html", line 1, in top-level template code
    {% block doc -%}
  File "/mnt/c/Users/ASUS/Documents/webdev/microblog/venv/lib/python3.8/site-packages/flask_bootstrap/templates/bootstrap/base.html", line 4, in block "doc"
    {%- block html %}
  File "/mnt/c/Users/ASUS/Documents/webdev/microblog/venv/lib/python3.8/site-packages/flask_bootstrap/templates/bootstrap/base.html", line 20, in block "html"
    {% block body -%}
  File "/mnt/c/Users/ASUS/Documents/webdev/microblog/venv/lib/python3.8/site-packages/flask_bootstrap/templates/bootstrap/base.html", line 23, in block "body"
    {% block content -%}
  File "/mnt/c/Users/ASUS/Documents/webdev/microblog/app/templates/base.html", line 49, in block "content"
    {% block app_content %}{% endblock %}
  File "/mnt/c/Users/ASUS/Documents/webdev/microblog/app/templates/index.html", line 5, in block "app_content"
    <h1> {{ _('Hi, %(username)!',username=current_user.username) }}</h1>
  File "/mnt/c/Users/ASUS/Documents/webdev/microblog/venv/lib/python3.8/site-packages/jinja2/ext.py", line 144, in _gettext_alias
    return __context.call(__context.resolve("gettext"), *args, **kwargs)
  File "/mnt/c/Users/ASUS/Documents/webdev/microblog/venv/lib/python3.8/site-packages/jinja2/ext.py", line 156, in gettext
    return rv % variables
  File "/mnt/c/Users/ASUS/Documents/webdev/microblog/venv/lib/python3.8/site-packages/markupsafe/__init__.py", line 102, in __mod__
    return self.__class__(text_type.__mod__(self, arg))
ValueError: unsupported format character '!' (0x21) at index 15
2020-08-12 01:11:34,029 ERROR: Exception on /explore [GET] [in /mnt/c/Users/ASUS/Documents/webdev/microblog/venv/lib/python3.8/site-packages/flask/app.py:1891]
Traceback (most recent call last):
  File "/mnt/c/Users/ASUS/Documents/webdev/microblog/venv/lib/python3.8/site-packages/flask/app.py", line 2447, in wsgi_app
    response = self.full_dispatch_request()
  File "/mnt/c/Users/ASUS/Documents/webdev/microblog/venv/lib/python3.8/site-packages/flask/app.py", line 1952, in full_dispatch_request
    rv = self.handle_user_exception(e)
  File "/mnt/c/Users/ASUS/Documents/webdev/microblog/venv/lib/python3.8/site-packages/flask/app.py", line 1821, in handle_user_exception
    reraise(exc_type, exc_value, tb)
  File "/mnt/c/Users/ASUS/Documents/webdev/microblog/venv/lib/python3.8/site-packages/flask/_compat.py", line 39, in reraise
    raise value
  File "/mnt/c/Users/ASUS/Documents/webdev/microblog/venv/lib/python3.8/site-packages/flask/app.py", line 1950, in full_dispatch_request
    rv = self.dispatch_request()
  File "/mnt/c/Users/ASUS/Documents/webdev/microblog/venv/lib/python3.8/site-packages/flask/app.py", line 1936, in dispatch_request
    return self.view_functions[rule.endpoint](**req.view_args)
  File "/mnt/c/Users/ASUS/Documents/webdev/microblog/venv/lib/python3.8/site-packages/flask_login/utils.py", line 272, in decorated_view
    return func(*args, **kwargs)
  File "/mnt/c/Users/ASUS/Documents/webdev/microblog/app/routes.py", line 158, in explore
    return render_template("index.html", title='Explore', posts=posts.items,
  File "/mnt/c/Users/ASUS/Documents/webdev/microblog/venv/lib/python3.8/site-packages/flask/templating.py", line 137, in render_template
    return _render(
  File "/mnt/c/Users/ASUS/Documents/webdev/microblog/venv/lib/python3.8/site-packages/flask/templating.py", line 120, in _render
    rv = template.render(context)
  File "/mnt/c/Users/ASUS/Documents/webdev/microblog/venv/lib/python3.8/site-packages/jinja2/environment.py", line 1090, in render
    self.environment.handle_exception()
  File "/mnt/c/Users/ASUS/Documents/webdev/microblog/venv/lib/python3.8/site-packages/jinja2/environment.py", line 832, in handle_exception
    reraise(*rewrite_traceback_stack(source=source))
  File "/mnt/c/Users/ASUS/Documents/webdev/microblog/venv/lib/python3.8/site-packages/jinja2/_compat.py", line 28, in reraise
    raise value.with_traceback(tb)
  File "/mnt/c/Users/ASUS/Documents/webdev/microblog/app/templates/index.html", line 2, in top-level template code
    {% import 'bootstrap/wtf.html' as wtf %}
  File "/mnt/c/Users/ASUS/Documents/webdev/microblog/app/templates/base.html", line 1, in top-level template code
    {% extends 'bootstrap/base.html' %}
  File "/mnt/c/Users/ASUS/Documents/webdev/microblog/venv/lib/python3.8/site-packages/flask_bootstrap/templates/bootstrap/base.html", line 1, in top-level template code
    {% block doc -%}
  File "/mnt/c/Users/ASUS/Documents/webdev/microblog/venv/lib/python3.8/site-packages/flask_bootstrap/templates/bootstrap/base.html", line 4, in block "doc"
    {%- block html %}
  File "/mnt/c/Users/ASUS/Documents/webdev/microblog/venv/lib/python3.8/site-packages/flask_bootstrap/templates/bootstrap/base.html", line 20, in block "html"
    {% block body -%}
  File "/mnt/c/Users/ASUS/Documents/webdev/microblog/venv/lib/python3.8/site-packages/flask_bootstrap/templates/bootstrap/base.html", line 23, in block "body"
    {% block content -%}
  File "/mnt/c/Users/ASUS/Documents/webdev/microblog/app/templates/base.html", line 49, in block "content"
    {% block app_content %}{% endblock %}
  File "/mnt/c/Users/ASUS/Documents/webdev/microblog/app/templates/index.html", line 5, in block "app_content"
    <h1> {{ _('Hi, %(username)!',username=current_user.username) }}</h1>
  File "/mnt/c/Users/ASUS/Documents/webdev/microblog/venv/lib/python3.8/site-packages/jinja2/ext.py", line 144, in _gettext_alias
    return __context.call(__context.resolve("gettext"), *args, **kwargs)
  File "/mnt/c/Users/ASUS/Documents/webdev/microblog/venv/lib/python3.8/site-packages/jinja2/ext.py", line 156, in gettext
    return rv % variables
  File "/mnt/c/Users/ASUS/Documents/webdev/microblog/venv/lib/python3.8/site-packages/markupsafe/__init__.py", line 102, in __mod__
    return self.__class__(text_type.__mod__(self, arg))
ValueError: unsupported format character '!' (0x21) at index 15
