2020-08-12 01:22:07,586 ERROR: Exception on /register [GET] [in /mnt/c/Users/ASUS/Documents/webdev/microblog/venv/lib/python3.8/site-packages/flask/app.py:1891]
Traceback (most recent call last):
  File "/mnt/c/Users/ASUS/Documents/webdev/microblog/venv/lib/python3.8/site-packages/flask/app.py", line 2447, in wsgi_app
    response = self.full_dispatch_request()
  File "/mnt/c/Users/ASUS/Documents/webdev/microblog/venv/lib/python3.8/site-packages/flask/app.py", line 1952, in full_dispatch_request
    rv = self.handle_user_exception(e)
  File "/mnt/c/Users/ASUS/Documents/webdev/microblog/venv/lib/python3.8/site-packages/flask/app.py", line 1821, in handle_user_exception
    reraise(exc_type, exc_value, tb)
  File "/mnt/c/Users/ASUS/Documents/webdev/microblog/venv/lib/python3.8/site-packages/flask/_compat.py", line 39, in reraise
    raise value
  File "/mnt/c/Users/ASUS/Documents/webdev/microblog/venv/lib/python3.8/site-packages/flask/app.py", line 1950, in full_dispatch_request
    rv = self.dispatch_request()
  File "/mnt/c/Users/ASUS/Documents/webdev/microblog/venv/lib/python3.8/site-packages/flask/app.py", line 1936, in dispatch_request
    return self.view_functions[rule.endpoint](**req.view_args)
  File "/mnt/c/Users/ASUS/Documents/webdev/microblog/app/routes.py", line 70, in register
    return render_template('register.html', title='Register', form=form)
  File "/mnt/c/Users/ASUS/Documents/webdev/microblog/venv/lib/python3.8/site-packages/flask/templating.py", line 138, in render_template
    ctx.app.jinja_env.get_or_select_template(template_name_or_list),
  File "/mnt/c/Users/ASUS/Documents/webdev/microblog/venv/lib/python3.8/site-packages/jinja2/environment.py", line 930, in get_or_select_template
    return self.get_template(template_name_or_list, parent, globals)
  File "/mnt/c/Users/ASUS/Documents/webdev/microblog/venv/lib/python3.8/site-packages/jinja2/environment.py", line 883, in get_template
    return self._load_template(name, self.make_globals(globals))
  File "/mnt/c/Users/ASUS/Documents/webdev/microblog/venv/lib/python3.8/site-packages/jinja2/environment.py", line 857, in _load_template
    template = self.loader.load(self, name, globals)
  File "/mnt/c/Users/ASUS/Documents/webdev/microblog/venv/lib/python3.8/site-packages/jinja2/loaders.py", line 127, in load
    code = environment.compile(source, name, filename)
  File "/mnt/c/Users/ASUS/Documents/webdev/microblog/venv/lib/python3.8/site-packages/jinja2/environment.py", line 638, in compile
    self.handle_exception(source=source_hint)
  File "/mnt/c/Users/ASUS/Documents/webdev/microblog/venv/lib/python3.8/site-packages/jinja2/environment.py", line 832, in handle_exception
    reraise(*rewrite_traceback_stack(source=source))
  File "/mnt/c/Users/ASUS/Documents/webdev/microblog/venv/lib/python3.8/site-packages/jinja2/_compat.py", line 28, in reraise
    raise value.with_traceback(tb)
  File "/mnt/c/Users/ASUS/Documents/webdev/microblog/app/templates/register.html", line 14, in template
    {% block app_content %}
jinja2.exceptions.TemplateAssertionError: block 'app_content' defined twice
2020-08-12 01:24:03,609 INFO: Microblog startup [in /mnt/c/Users/ASUS/Documents/webdev/microblog/app/__init__.py:53]
2020-08-12 01:28:26,467 INFO: Microblog startup [in /mnt/c/Users/ASUS/Documents/webdev/microblog/app/__init__.py:53]
2020-08-12 01:38:40,160 INFO: Microblog startup [in /mnt/c/Users/ASUS/Documents/webdev/microblog/app/__init__.py:53]
2020-08-12 01:39:27,478 INFO: Microblog startup [in /mnt/c/Users/ASUS/Documents/webdev/microblog/app/__init__.py:53]
2020-08-12 01:44:34,453 INFO: Microblog startup [in /mnt/c/Users/ASUS/Documents/webdev/microblog/app/__init__.py:53]
2020-08-12 01:45:04,985 INFO: Microblog startup [in /mnt/c/Users/ASUS/Documents/webdev/microblog/app/__init__.py:53]
2020-08-12 11:16:36,689 INFO: Microblog startup [in /mnt/c/Users/ASUS/Documents/webdev/microblog/app/__init__.py:53]
2020-08-12 11:16:54,704 INFO: Microblog startup [in /mnt/c/Users/ASUS/Documents/webdev/microblog/app/__init__.py:53]
2020-08-12 12:13:31,465 INFO: Microblog startup [in /mnt/c/Users/ASUS/Documents/webdev/microblog/app/__init__.py:53]
2020-08-12 12:13:39,331 INFO: Microblog startup [in /mnt/c/Users/ASUS/Documents/webdev/microblog/app/__init__.py:53]
2020-08-12 12:13:44,251 INFO: Microblog startup [in /mnt/c/Users/ASUS/Documents/webdev/microblog/app/__init__.py:53]
2020-08-12 12:13:46,711 ERROR: Exception on /login [GET] [in /mnt/c/Users/ASUS/Documents/webdev/microblog/venv/lib/python3.8/site-packages/flask/app.py:1891]
Traceback (most recent call last):
  File "/mnt/c/Users/ASUS/Documents/webdev/microblog/venv/lib/python3.8/site-packages/flask/app.py", line 2447, in wsgi_app
    response = self.full_dispatch_request()
  File "/mnt/c/Users/ASUS/Documents/webdev/microblog/venv/lib/python3.8/site-packages/flask/app.py", line 1952, in full_dispatch_request
    rv = self.handle_user_exception(e)
  File "/mnt/c/Users/ASUS/Documents/webdev/microblog/venv/lib/python3.8/site-packages/flask/app.py", line 1821, in handle_user_exception
    reraise(exc_type, exc_value, tb)
  File "/mnt/c/Users/ASUS/Documents/webdev/microblog/venv/lib/python3.8/site-packages/flask/_compat.py", line 39, in reraise
    raise value
  File "/mnt/c/Users/ASUS/Documents/webdev/microblog/venv/lib/python3.8/site-packages/flask/app.py", line 1950, in full_dispatch_request
    rv = self.dispatch_request()
  File "/mnt/c/Users/ASUS/Documents/webdev/microblog/venv/lib/python3.8/site-packages/flask/app.py", line 1936, in dispatch_request
    return self.view_functions[rule.endpoint](**req.view_args)
  File "/mnt/c/Users/ASUS/Documents/webdev/microblog/app/routes.py", line 56, in login
    return render_template('login.html', title='Sign In', form=form)
  File "/mnt/c/Users/ASUS/Documents/webdev/microblog/venv/lib/python3.8/site-packages/flask/templating.py", line 137, in render_template
    return _render(
  File "/mnt/c/Users/ASUS/Documents/webdev/microblog/venv/lib/python3.8/site-packages/flask/templating.py", line 120, in _render
    rv = template.render(context)
  File "/mnt/c/Users/ASUS/Documents/webdev/microblog/venv/lib/python3.8/site-packages/jinja2/environment.py", line 1090, in render
    self.environment.handle_exception()
  File "/mnt/c/Users/ASUS/Documents/webdev/microblog/venv/lib/python3.8/site-packages/jinja2/environment.py", line 832, in handle_exception
    reraise(*rewrite_traceback_stack(source=source))
  File "/mnt/c/Users/ASUS/Documents/webdev/microblog/venv/lib/python3.8/site-packages/jinja2/_compat.py", line 28, in reraise
    raise value.with_traceback(tb)
  File "/mnt/c/Users/ASUS/Documents/webdev/microblog/app/templates/login.html", line 2, in top-level template code
    {% import 'bootstrap/wtf.html' as wtf %}
  File "/mnt/c/Users/ASUS/Documents/webdev/microblog/app/templates/base.html", line 1, in top-level template code
    {% extends 'bootstrap/base.html' %}
  File "/mnt/c/Users/ASUS/Documents/webdev/microblog/venv/lib/python3.8/site-packages/flask_bootstrap/templates/bootstrap/base.html", line 1, in top-level template code
    {% block doc -%}
  File "/mnt/c/Users/ASUS/Documents/webdev/microblog/venv/lib/python3.8/site-packages/flask_bootstrap/templates/bootstrap/base.html", line 4, in block "doc"
    {%- block html %}
  File "/mnt/c/Users/ASUS/Documents/webdev/microblog/venv/lib/python3.8/site-packages/flask_bootstrap/templates/bootstrap/base.html", line 20, in block "html"
    {% block body -%}
  File "/mnt/c/Users/ASUS/Documents/webdev/microblog/venv/lib/python3.8/site-packages/flask_bootstrap/templates/bootstrap/base.html", line 26, in block "body"
    {% block scripts %}
  File "/mnt/c/Users/ASUS/Documents/webdev/microblog/app/templates/base.html", line 59, in block "scripts"
    $(destElem).html('<img src="{{ url_for(', static, ', filename=', loading.gif, ') }}">');
  File "/mnt/c/Users/ASUS/Documents/webdev/microblog/venv/lib/python3.8/site-packages/flask/helpers.py", line 370, in url_for
    return appctx.app.handle_url_build_error(error, endpoint, values)
  File "/mnt/c/Users/ASUS/Documents/webdev/microblog/venv/lib/python3.8/site-packages/flask/app.py", line 2216, in handle_url_build_error
    reraise(exc_type, exc_value, tb)
  File "/mnt/c/Users/ASUS/Documents/webdev/microblog/venv/lib/python3.8/site-packages/flask/_compat.py", line 39, in reraise
    raise value
  File "/mnt/c/Users/ASUS/Documents/webdev/microblog/venv/lib/python3.8/site-packages/flask/helpers.py", line 357, in url_for
    rv = url_adapter.build(
  File "/mnt/c/Users/ASUS/Documents/webdev/microblog/venv/lib/python3.8/site-packages/werkzeug/routing.py", line 2179, in build
    raise BuildError(endpoint, values, method, self)
werkzeug.routing.BuildError: Could not build url for endpoint ', static, ' with values ['filename']. Did you mean 'static' instead?
